INFO 2024-05-30 17:16:26,373 guardian Publication Date: 27 May 2024
ERROR 2024-05-30 18:22:58,358 log Internal Server Error: /myfess/
Traceback (most recent call last):
  File "e:\Python39\venv\lib\site-packages\django\core\handlers\exception.py", line 55, in inner
    response = get_response(request)
  File "e:\Python39\venv\lib\site-packages\django\core\handlers\base.py", line 220, in _get_response
    response = response.render()
  File "e:\Python39\venv\lib\site-packages\django\template\response.py", line 114, in render
    self.content = self.rendered_content
  File "e:\Python39\venv\lib\site-packages\rest_framework\response.py", line 74, in rendered_content
    ret = renderer.render(self.data, accepted_media_type, context)
  File "e:\Python39\venv\lib\site-packages\rest_framework\renderers.py", line 99, in render
    ret = json.dumps(
  File "e:\Python39\venv\lib\site-packages\rest_framework\utils\json.py", line 25, in dumps
    return json.dumps(*args, **kwargs)
  File "E:\Python39\lib\json\__init__.py", line 234, in dumps
    return cls(
  File "E:\Python39\lib\json\encoder.py", line 199, in encode
    chunks = self.iterencode(o, _one_shot=True)
  File "E:\Python39\lib\json\encoder.py", line 257, in iterencode
    return _iterencode(o, 0)
  File "e:\Python39\venv\lib\site-packages\rest_framework\utils\encoders.py", line 67, in default
    return super().default(obj)
  File "E:\Python39\lib\json\encoder.py", line 179, in default
    raise TypeError(f'Object of type {o.__class__.__name__} '
TypeError: Object of type Response is not JSON serializable
ERROR 2024-05-30 18:22:58,380 basehttp "POST /myfess/ HTTP/1.1" 500 101677
ERROR 2024-05-30 18:26:39,681 log Internal Server Error: /myfess/
Traceback (most recent call last):
  File "e:\Python39\venv\lib\site-packages\django\core\handlers\exception.py", line 55, in inner
    response = get_response(request)
  File "e:\Python39\venv\lib\site-packages\django\core\handlers\base.py", line 197, in _get_response
    response = wrapped_callback(request, *callback_args, **callback_kwargs)
  File "e:\Python39\venv\lib\site-packages\django\views\decorators\csrf.py", line 56, in wrapper_view
    return view_func(*args, **kwargs)
  File "e:\Python39\venv\lib\site-packages\django\views\generic\base.py", line 104, in view
    return self.dispatch(request, *args, **kwargs)
  File "e:\Python39\venv\lib\site-packages\rest_framework\views.py", line 509, in dispatch
    response = self.handle_exception(exc)
  File "e:\Python39\venv\lib\site-packages\rest_framework\views.py", line 469, in handle_exception
    self.raise_uncaught_exception(exc)
  File "e:\Python39\venv\lib\site-packages\rest_framework\views.py", line 480, in raise_uncaught_exception
    raise exc
  File "e:\Python39\venv\lib\site-packages\rest_framework\views.py", line 506, in dispatch
    response = handler(request, *args, **kwargs)
  File "e:\Python39\venv\lib\site-packages\rest_framework\decorators.py", line 50, in handler
    return func(*args, **kwargs)
  File "E:\FessScrapper_project\FessApp\views\common.py", line 43, in Fess_split_Post
    full_path=Fess_hbr_Post(request)
  File "E:\FessScrapper_project\FessApp\views\hbr.py", line 104, in Fess_hbr_Post
    publication_date, title, text , full_path= Fetch_Content(link,collection_name)
ValueError: too many values to unpack (expected 4)
ERROR 2024-05-30 18:26:39,694 basehttp "POST /myfess/ HTTP/1.1" 500 100533
ERROR 2024-05-30 18:33:26,326 log Internal Server Error: /myfess/
Traceback (most recent call last):
  File "e:\Python39\venv\lib\site-packages\django\core\handlers\exception.py", line 55, in inner
    response = get_response(request)
  File "e:\Python39\venv\lib\site-packages\django\core\handlers\base.py", line 197, in _get_response
    response = wrapped_callback(request, *callback_args, **callback_kwargs)
  File "e:\Python39\venv\lib\site-packages\django\views\decorators\csrf.py", line 56, in wrapper_view
    return view_func(*args, **kwargs)
  File "e:\Python39\venv\lib\site-packages\django\views\generic\base.py", line 104, in view
    return self.dispatch(request, *args, **kwargs)
  File "e:\Python39\venv\lib\site-packages\rest_framework\views.py", line 509, in dispatch
    response = self.handle_exception(exc)
  File "e:\Python39\venv\lib\site-packages\rest_framework\views.py", line 469, in handle_exception
    self.raise_uncaught_exception(exc)
  File "e:\Python39\venv\lib\site-packages\rest_framework\views.py", line 480, in raise_uncaught_exception
    raise exc
  File "e:\Python39\venv\lib\site-packages\rest_framework\views.py", line 506, in dispatch
    response = handler(request, *args, **kwargs)
  File "e:\Python39\venv\lib\site-packages\rest_framework\decorators.py", line 50, in handler
    return func(*args, **kwargs)
  File "E:\FessScrapper_project\FessApp\views\common.py", line 43, in Fess_split_Post
    full_path=Fess_hbr_Post(request)
  File "E:\FessScrapper_project\FessApp\views\hbr.py", line 100, in Fess_hbr_Post
    publication_date, title, text , full_path= Fetch_Content(link,collection_name)
  File "E:\FessScrapper_project\FessApp\views\hbr.py", line 52, in Fetch_Content
    if 'setContentCreated' in script.string:
TypeError: argument of type 'NoneType' is not iterable
ERROR 2024-05-30 18:33:26,351 basehttp "POST /myfess/ HTTP/1.1" 500 121868
ERROR 2024-05-30 18:38:35,817 log Internal Server Error: /myfess/
Traceback (most recent call last):
  File "e:\Python39\venv\lib\site-packages\django\core\handlers\exception.py", line 55, in inner
    response = get_response(request)
  File "e:\Python39\venv\lib\site-packages\django\core\handlers\base.py", line 197, in _get_response
    response = wrapped_callback(request, *callback_args, **callback_kwargs)
  File "e:\Python39\venv\lib\site-packages\django\views\decorators\csrf.py", line 56, in wrapper_view
    return view_func(*args, **kwargs)
  File "e:\Python39\venv\lib\site-packages\django\views\generic\base.py", line 104, in view
    return self.dispatch(request, *args, **kwargs)
  File "e:\Python39\venv\lib\site-packages\rest_framework\views.py", line 509, in dispatch
    response = self.handle_exception(exc)
  File "e:\Python39\venv\lib\site-packages\rest_framework\views.py", line 469, in handle_exception
    self.raise_uncaught_exception(exc)
  File "e:\Python39\venv\lib\site-packages\rest_framework\views.py", line 480, in raise_uncaught_exception
    raise exc
  File "e:\Python39\venv\lib\site-packages\rest_framework\views.py", line 506, in dispatch
    response = handler(request, *args, **kwargs)
  File "e:\Python39\venv\lib\site-packages\rest_framework\decorators.py", line 50, in handler
    return func(*args, **kwargs)
  File "E:\FessScrapper_project\FessApp\views\common.py", line 43, in Fess_split_Post
    full_path=Fess_hbr_Post(request)
  File "E:\FessScrapper_project\FessApp\views\hbr.py", line 102, in Fess_hbr_Post
    publication_date, title, text , full_path= Fetch_Content(link,collection_name)
  File "E:\FessScrapper_project\FessApp\views\hbr.py", line 54, in Fetch_Content
    if 'setContentCreated' in script.string:
TypeError: argument of type 'NoneType' is not iterable
ERROR 2024-05-30 18:38:35,835 basehttp "POST /myfess/ HTTP/1.1" 500 121462
ERROR 2024-05-30 18:57:12,872 log Internal Server Error: /myfess/
Traceback (most recent call last):
  File "e:\Python39\venv\lib\site-packages\django\core\handlers\exception.py", line 55, in inner
    response = get_response(request)
  File "e:\Python39\venv\lib\site-packages\django\core\handlers\base.py", line 197, in _get_response
    response = wrapped_callback(request, *callback_args, **callback_kwargs)
  File "e:\Python39\venv\lib\site-packages\django\views\decorators\csrf.py", line 56, in wrapper_view
    return view_func(*args, **kwargs)
  File "e:\Python39\venv\lib\site-packages\django\views\generic\base.py", line 104, in view
    return self.dispatch(request, *args, **kwargs)
  File "e:\Python39\venv\lib\site-packages\rest_framework\views.py", line 509, in dispatch
    response = self.handle_exception(exc)
  File "e:\Python39\venv\lib\site-packages\rest_framework\views.py", line 469, in handle_exception
    self.raise_uncaught_exception(exc)
  File "e:\Python39\venv\lib\site-packages\rest_framework\views.py", line 480, in raise_uncaught_exception
    raise exc
  File "e:\Python39\venv\lib\site-packages\rest_framework\views.py", line 506, in dispatch
    response = handler(request, *args, **kwargs)
  File "e:\Python39\venv\lib\site-packages\rest_framework\decorators.py", line 50, in handler
    return func(*args, **kwargs)
  File "E:\FessScrapper_project\FessApp\views\common.py", line 43, in Fess_split_Post
    full_path=Fess_hbr_Post(request)
  File "E:\FessScrapper_project\FessApp\views\hbr.py", line 103, in Fess_hbr_Post
    publication_date, title, text , full_path= Fetch_Content(link,collection_name)
  File "E:\FessScrapper_project\FessApp\views\hbr.py", line 55, in Fetch_Content
    if 'setContentCreated' in script.string:
TypeError: argument of type 'NoneType' is not iterable
ERROR 2024-05-30 18:57:12,893 basehttp "POST /myfess/ HTTP/1.1" 500 121432
ERROR 2024-05-30 19:05:15,879 log Internal Server Error: /myfess/
Traceback (most recent call last):
  File "e:\Python39\venv\lib\site-packages\django\core\handlers\exception.py", line 55, in inner
    response = get_response(request)
  File "e:\Python39\venv\lib\site-packages\django\core\handlers\base.py", line 220, in _get_response
    response = response.render()
  File "e:\Python39\venv\lib\site-packages\django\template\response.py", line 114, in render
    self.content = self.rendered_content
  File "e:\Python39\venv\lib\site-packages\rest_framework\response.py", line 74, in rendered_content
    ret = renderer.render(self.data, accepted_media_type, context)
  File "e:\Python39\venv\lib\site-packages\rest_framework\renderers.py", line 99, in render
    ret = json.dumps(
  File "e:\Python39\venv\lib\site-packages\rest_framework\utils\json.py", line 25, in dumps
    return json.dumps(*args, **kwargs)
  File "E:\Python39\lib\json\__init__.py", line 234, in dumps
    return cls(
  File "E:\Python39\lib\json\encoder.py", line 199, in encode
    chunks = self.iterencode(o, _one_shot=True)
  File "E:\Python39\lib\json\encoder.py", line 257, in iterencode
    return _iterencode(o, 0)
  File "e:\Python39\venv\lib\site-packages\rest_framework\utils\encoders.py", line 67, in default
    return super().default(obj)
  File "E:\Python39\lib\json\encoder.py", line 179, in default
    raise TypeError(f'Object of type {o.__class__.__name__} '
TypeError: Object of type Response is not JSON serializable
ERROR 2024-05-30 19:05:15,899 basehttp "POST /myfess/ HTTP/1.1" 500 101677
ERROR 2024-05-30 19:13:29,758 log Internal Server Error: /myfess/
Traceback (most recent call last):
  File "e:\Python39\venv\lib\site-packages\django\core\handlers\exception.py", line 55, in inner
    response = get_response(request)
  File "e:\Python39\venv\lib\site-packages\django\core\handlers\base.py", line 220, in _get_response
    response = response.render()
  File "e:\Python39\venv\lib\site-packages\django\template\response.py", line 114, in render
    self.content = self.rendered_content
  File "e:\Python39\venv\lib\site-packages\rest_framework\response.py", line 74, in rendered_content
    ret = renderer.render(self.data, accepted_media_type, context)
  File "e:\Python39\venv\lib\site-packages\rest_framework\renderers.py", line 99, in render
    ret = json.dumps(
  File "e:\Python39\venv\lib\site-packages\rest_framework\utils\json.py", line 25, in dumps
    return json.dumps(*args, **kwargs)
  File "E:\Python39\lib\json\__init__.py", line 234, in dumps
    return cls(
  File "E:\Python39\lib\json\encoder.py", line 199, in encode
    chunks = self.iterencode(o, _one_shot=True)
  File "E:\Python39\lib\json\encoder.py", line 257, in iterencode
    return _iterencode(o, 0)
  File "e:\Python39\venv\lib\site-packages\rest_framework\utils\encoders.py", line 67, in default
    return super().default(obj)
  File "E:\Python39\lib\json\encoder.py", line 179, in default
    raise TypeError(f'Object of type {o.__class__.__name__} '
TypeError: Object of type Response is not JSON serializable
ERROR 2024-05-30 19:13:29,772 basehttp "POST /myfess/ HTTP/1.1" 500 101677
ERROR 2024-05-30 19:26:28,038 log Internal Server Error: /myfess/
Traceback (most recent call last):
  File "e:\Python39\venv\lib\site-packages\django\core\handlers\exception.py", line 55, in inner
    response = get_response(request)
  File "e:\Python39\venv\lib\site-packages\django\core\handlers\base.py", line 220, in _get_response
    response = response.render()
  File "e:\Python39\venv\lib\site-packages\django\template\response.py", line 114, in render
    self.content = self.rendered_content
  File "e:\Python39\venv\lib\site-packages\rest_framework\response.py", line 74, in rendered_content
    ret = renderer.render(self.data, accepted_media_type, context)
  File "e:\Python39\venv\lib\site-packages\rest_framework\renderers.py", line 99, in render
    ret = json.dumps(
  File "e:\Python39\venv\lib\site-packages\rest_framework\utils\json.py", line 25, in dumps
    return json.dumps(*args, **kwargs)
  File "E:\Python39\lib\json\__init__.py", line 234, in dumps
    return cls(
  File "E:\Python39\lib\json\encoder.py", line 199, in encode
    chunks = self.iterencode(o, _one_shot=True)
  File "E:\Python39\lib\json\encoder.py", line 257, in iterencode
    return _iterencode(o, 0)
  File "e:\Python39\venv\lib\site-packages\rest_framework\utils\encoders.py", line 67, in default
    return super().default(obj)
  File "E:\Python39\lib\json\encoder.py", line 179, in default
    raise TypeError(f'Object of type {o.__class__.__name__} '
TypeError: Object of type Response is not JSON serializable
ERROR 2024-05-30 19:26:28,059 basehttp "POST /myfess/ HTTP/1.1" 500 101677
ERROR 2024-05-30 19:28:13,297 log Internal Server Error: /myfess/
Traceback (most recent call last):
  File "e:\Python39\venv\lib\site-packages\django\core\handlers\exception.py", line 55, in inner
    response = get_response(request)
  File "e:\Python39\venv\lib\site-packages\django\core\handlers\base.py", line 220, in _get_response
    response = response.render()
  File "e:\Python39\venv\lib\site-packages\django\template\response.py", line 114, in render
    self.content = self.rendered_content
  File "e:\Python39\venv\lib\site-packages\rest_framework\response.py", line 74, in rendered_content
    ret = renderer.render(self.data, accepted_media_type, context)
  File "e:\Python39\venv\lib\site-packages\rest_framework\renderers.py", line 99, in render
    ret = json.dumps(
  File "e:\Python39\venv\lib\site-packages\rest_framework\utils\json.py", line 25, in dumps
    return json.dumps(*args, **kwargs)
  File "E:\Python39\lib\json\__init__.py", line 234, in dumps
    return cls(
  File "E:\Python39\lib\json\encoder.py", line 199, in encode
    chunks = self.iterencode(o, _one_shot=True)
  File "E:\Python39\lib\json\encoder.py", line 257, in iterencode
    return _iterencode(o, 0)
  File "e:\Python39\venv\lib\site-packages\rest_framework\utils\encoders.py", line 67, in default
    return super().default(obj)
  File "E:\Python39\lib\json\encoder.py", line 179, in default
    raise TypeError(f'Object of type {o.__class__.__name__} '
TypeError: Object of type Response is not JSON serializable
ERROR 2024-05-30 19:28:13,317 basehttp "POST /myfess/ HTTP/1.1" 500 101677
ERROR 2024-05-30 19:38:22,779 log Internal Server Error: /myfess/
Traceback (most recent call last):
  File "e:\Python39\venv\lib\site-packages\django\core\handlers\exception.py", line 55, in inner
    response = get_response(request)
  File "e:\Python39\venv\lib\site-packages\django\core\handlers\base.py", line 197, in _get_response
    response = wrapped_callback(request, *callback_args, **callback_kwargs)
  File "e:\Python39\venv\lib\site-packages\django\views\decorators\csrf.py", line 56, in wrapper_view
    return view_func(*args, **kwargs)
  File "e:\Python39\venv\lib\site-packages\django\views\generic\base.py", line 104, in view
    return self.dispatch(request, *args, **kwargs)
  File "e:\Python39\venv\lib\site-packages\rest_framework\views.py", line 509, in dispatch
    response = self.handle_exception(exc)
  File "e:\Python39\venv\lib\site-packages\rest_framework\views.py", line 469, in handle_exception
    self.raise_uncaught_exception(exc)
  File "e:\Python39\venv\lib\site-packages\rest_framework\views.py", line 480, in raise_uncaught_exception
    raise exc
  File "e:\Python39\venv\lib\site-packages\rest_framework\views.py", line 506, in dispatch
    response = handler(request, *args, **kwargs)
  File "e:\Python39\venv\lib\site-packages\rest_framework\decorators.py", line 50, in handler
    return func(*args, **kwargs)
  File "E:\FessScrapper_project\FessApp\views\common.py", line 43, in Fess_split_Post
    full_path=Fess_hbr_Post(request)
  File "E:\FessScrapper_project\FessApp\views\hbr.py", line 98, in Fess_hbr_Post
    publication_date, title, text , full_path= Fetch_Content(link,collection_name)
ValueError: too many values to unpack (expected 4)
ERROR 2024-05-30 19:38:22,794 basehttp "POST /myfess/ HTTP/1.1" 500 100960
ERROR 2024-05-30 19:54:26,136 log Internal Server Error: /myfess/
Traceback (most recent call last):
  File "e:\Python39\venv\lib\site-packages\django\core\handlers\exception.py", line 55, in inner
    response = get_response(request)
  File "e:\Python39\venv\lib\site-packages\django\core\handlers\base.py", line 197, in _get_response
    response = wrapped_callback(request, *callback_args, **callback_kwargs)
  File "e:\Python39\venv\lib\site-packages\django\views\decorators\csrf.py", line 56, in wrapper_view
    return view_func(*args, **kwargs)
  File "e:\Python39\venv\lib\site-packages\django\views\generic\base.py", line 104, in view
    return self.dispatch(request, *args, **kwargs)
  File "e:\Python39\venv\lib\site-packages\rest_framework\views.py", line 509, in dispatch
    response = self.handle_exception(exc)
  File "e:\Python39\venv\lib\site-packages\rest_framework\views.py", line 469, in handle_exception
    self.raise_uncaught_exception(exc)
  File "e:\Python39\venv\lib\site-packages\rest_framework\views.py", line 480, in raise_uncaught_exception
    raise exc
  File "e:\Python39\venv\lib\site-packages\rest_framework\views.py", line 506, in dispatch
    response = handler(request, *args, **kwargs)
  File "e:\Python39\venv\lib\site-packages\rest_framework\decorators.py", line 50, in handler
    return func(*args, **kwargs)
  File "E:\FessScrapper_project\FessApp\views\common.py", line 43, in Fess_split_Post
    full_path=Fess_hbr_Post(request)
  File "E:\FessScrapper_project\FessApp\views\hbr.py", line 98, in Fess_hbr_Post
    publication_date, title, text , full_path= Fetch_Content(link,collection_name)
ValueError: too many values to unpack (expected 4)
ERROR 2024-05-30 19:54:26,147 basehttp "POST /myfess/ HTTP/1.1" 500 100528
ERROR 2024-05-30 19:56:45,743 log Internal Server Error: /myfess/
Traceback (most recent call last):
  File "e:\Python39\venv\lib\site-packages\django\core\handlers\exception.py", line 55, in inner
    response = get_response(request)
  File "e:\Python39\venv\lib\site-packages\django\core\handlers\base.py", line 197, in _get_response
    response = wrapped_callback(request, *callback_args, **callback_kwargs)
  File "e:\Python39\venv\lib\site-packages\django\views\decorators\csrf.py", line 56, in wrapper_view
    return view_func(*args, **kwargs)
  File "e:\Python39\venv\lib\site-packages\django\views\generic\base.py", line 104, in view
    return self.dispatch(request, *args, **kwargs)
  File "e:\Python39\venv\lib\site-packages\rest_framework\views.py", line 509, in dispatch
    response = self.handle_exception(exc)
  File "e:\Python39\venv\lib\site-packages\rest_framework\views.py", line 469, in handle_exception
    self.raise_uncaught_exception(exc)
  File "e:\Python39\venv\lib\site-packages\rest_framework\views.py", line 480, in raise_uncaught_exception
    raise exc
  File "e:\Python39\venv\lib\site-packages\rest_framework\views.py", line 506, in dispatch
    response = handler(request, *args, **kwargs)
  File "e:\Python39\venv\lib\site-packages\rest_framework\decorators.py", line 50, in handler
    return func(*args, **kwargs)
  File "E:\FessScrapper_project\FessApp\views\common.py", line 43, in Fess_split_Post
    full_path=Fess_hbr_Post(request)
  File "E:\FessScrapper_project\FessApp\views\hbr.py", line 98, in Fess_hbr_Post
    publication_date, title, text , full_path= Fetch_Content(link,collection_name)
ValueError: too many values to unpack (expected 4)
ERROR 2024-05-30 19:56:45,760 basehttp "POST /myfess/ HTTP/1.1" 500 100950
ERROR 2024-05-30 19:57:18,552 log Internal Server Error: /myfess/
Traceback (most recent call last):
  File "e:\Python39\venv\lib\site-packages\django\core\handlers\exception.py", line 55, in inner
    response = get_response(request)
  File "e:\Python39\venv\lib\site-packages\django\core\handlers\base.py", line 197, in _get_response
    response = wrapped_callback(request, *callback_args, **callback_kwargs)
  File "e:\Python39\venv\lib\site-packages\django\views\decorators\csrf.py", line 56, in wrapper_view
    return view_func(*args, **kwargs)
  File "e:\Python39\venv\lib\site-packages\django\views\generic\base.py", line 104, in view
    return self.dispatch(request, *args, **kwargs)
  File "e:\Python39\venv\lib\site-packages\rest_framework\views.py", line 509, in dispatch
    response = self.handle_exception(exc)
  File "e:\Python39\venv\lib\site-packages\rest_framework\views.py", line 469, in handle_exception
    self.raise_uncaught_exception(exc)
  File "e:\Python39\venv\lib\site-packages\rest_framework\views.py", line 480, in raise_uncaught_exception
    raise exc
  File "e:\Python39\venv\lib\site-packages\rest_framework\views.py", line 506, in dispatch
    response = handler(request, *args, **kwargs)
  File "e:\Python39\venv\lib\site-packages\rest_framework\decorators.py", line 50, in handler
    return func(*args, **kwargs)
  File "E:\FessScrapper_project\FessApp\views\common.py", line 43, in Fess_split_Post
    full_path=Fess_hbr_Post(request)
  File "E:\FessScrapper_project\FessApp\views\hbr.py", line 98, in Fess_hbr_Post
    publication_date, title, text , full_path= Fetch_Content(link,collection_name)
ValueError: too many values to unpack (expected 4)
ERROR 2024-05-30 19:57:18,553 basehttp "POST /myfess/ HTTP/1.1" 500 100528
ERROR 2024-05-30 19:58:31,718 log Internal Server Error: /myfess/
Traceback (most recent call last):
  File "e:\Python39\venv\lib\site-packages\django\core\handlers\exception.py", line 55, in inner
    response = get_response(request)
  File "e:\Python39\venv\lib\site-packages\django\core\handlers\base.py", line 197, in _get_response
    response = wrapped_callback(request, *callback_args, **callback_kwargs)
  File "e:\Python39\venv\lib\site-packages\django\views\decorators\csrf.py", line 56, in wrapper_view
    return view_func(*args, **kwargs)
  File "e:\Python39\venv\lib\site-packages\django\views\generic\base.py", line 104, in view
    return self.dispatch(request, *args, **kwargs)
  File "e:\Python39\venv\lib\site-packages\rest_framework\views.py", line 509, in dispatch
    response = self.handle_exception(exc)
  File "e:\Python39\venv\lib\site-packages\rest_framework\views.py", line 469, in handle_exception
    self.raise_uncaught_exception(exc)
  File "e:\Python39\venv\lib\site-packages\rest_framework\views.py", line 480, in raise_uncaught_exception
    raise exc
  File "e:\Python39\venv\lib\site-packages\rest_framework\views.py", line 506, in dispatch
    response = handler(request, *args, **kwargs)
  File "e:\Python39\venv\lib\site-packages\rest_framework\decorators.py", line 50, in handler
    return func(*args, **kwargs)
  File "E:\FessScrapper_project\FessApp\views\common.py", line 43, in Fess_split_Post
    full_path=Fess_hbr_Post(request)
  File "E:\FessScrapper_project\FessApp\views\hbr.py", line 98, in Fess_hbr_Post
    publication_date, title, text , full_path= Fetch_Content(link,collection_name)
ValueError: too many values to unpack (expected 4)
ERROR 2024-05-30 19:58:31,734 basehttp "POST /myfess/ HTTP/1.1" 500 101001
ERROR 2024-05-30 19:59:22,627 log Internal Server Error: /myfess/
Traceback (most recent call last):
  File "e:\Python39\venv\lib\site-packages\django\core\handlers\exception.py", line 55, in inner
    response = get_response(request)
  File "e:\Python39\venv\lib\site-packages\django\core\handlers\base.py", line 197, in _get_response
    response = wrapped_callback(request, *callback_args, **callback_kwargs)
  File "e:\Python39\venv\lib\site-packages\django\views\decorators\csrf.py", line 56, in wrapper_view
    return view_func(*args, **kwargs)
  File "e:\Python39\venv\lib\site-packages\django\views\generic\base.py", line 104, in view
    return self.dispatch(request, *args, **kwargs)
  File "e:\Python39\venv\lib\site-packages\rest_framework\views.py", line 509, in dispatch
    response = self.handle_exception(exc)
  File "e:\Python39\venv\lib\site-packages\rest_framework\views.py", line 469, in handle_exception
    self.raise_uncaught_exception(exc)
  File "e:\Python39\venv\lib\site-packages\rest_framework\views.py", line 480, in raise_uncaught_exception
    raise exc
  File "e:\Python39\venv\lib\site-packages\rest_framework\views.py", line 506, in dispatch
    response = handler(request, *args, **kwargs)
  File "e:\Python39\venv\lib\site-packages\rest_framework\decorators.py", line 50, in handler
    return func(*args, **kwargs)
  File "E:\FessScrapper_project\FessApp\views\common.py", line 43, in Fess_split_Post
    full_path=Fess_hbr_Post(request)
  File "E:\FessScrapper_project\FessApp\views\hbr.py", line 98, in Fess_hbr_Post
    publication_date, title, text , full_path= Fetch_Content(link,collection_name)
ValueError: too many values to unpack (expected 4)
ERROR 2024-05-30 19:59:22,640 basehttp "POST /myfess/ HTTP/1.1" 500 100956
ERROR 2024-05-30 19:59:34,144 log Internal Server Error: /myfess/
Traceback (most recent call last):
  File "e:\Python39\venv\lib\site-packages\django\core\handlers\exception.py", line 55, in inner
    response = get_response(request)
  File "e:\Python39\venv\lib\site-packages\django\core\handlers\base.py", line 197, in _get_response
    response = wrapped_callback(request, *callback_args, **callback_kwargs)
  File "e:\Python39\venv\lib\site-packages\django\views\decorators\csrf.py", line 56, in wrapper_view
    return view_func(*args, **kwargs)
  File "e:\Python39\venv\lib\site-packages\django\views\generic\base.py", line 104, in view
    return self.dispatch(request, *args, **kwargs)
  File "e:\Python39\venv\lib\site-packages\rest_framework\views.py", line 509, in dispatch
    response = self.handle_exception(exc)
  File "e:\Python39\venv\lib\site-packages\rest_framework\views.py", line 469, in handle_exception
    self.raise_uncaught_exception(exc)
  File "e:\Python39\venv\lib\site-packages\rest_framework\views.py", line 480, in raise_uncaught_exception
    raise exc
  File "e:\Python39\venv\lib\site-packages\rest_framework\views.py", line 506, in dispatch
    response = handler(request, *args, **kwargs)
  File "e:\Python39\venv\lib\site-packages\rest_framework\decorators.py", line 50, in handler
    return func(*args, **kwargs)
  File "E:\FessScrapper_project\FessApp\views\common.py", line 43, in Fess_split_Post
    full_path=Fess_hbr_Post(request)
  File "E:\FessScrapper_project\FessApp\views\hbr.py", line 98, in Fess_hbr_Post
    publication_date, title, text , full_path= Fetch_Content(link,collection_name)
ValueError: too many values to unpack (expected 4)
ERROR 2024-05-30 19:59:34,147 basehttp "POST /myfess/ HTTP/1.1" 500 100528
ERROR 2024-05-30 19:59:55,024 log Internal Server Error: /myfess/
Traceback (most recent call last):
  File "e:\Python39\venv\lib\site-packages\django\core\handlers\exception.py", line 55, in inner
    response = get_response(request)
  File "e:\Python39\venv\lib\site-packages\django\core\handlers\base.py", line 197, in _get_response
    response = wrapped_callback(request, *callback_args, **callback_kwargs)
  File "e:\Python39\venv\lib\site-packages\django\views\decorators\csrf.py", line 56, in wrapper_view
    return view_func(*args, **kwargs)
  File "e:\Python39\venv\lib\site-packages\django\views\generic\base.py", line 104, in view
    return self.dispatch(request, *args, **kwargs)
  File "e:\Python39\venv\lib\site-packages\rest_framework\views.py", line 509, in dispatch
    response = self.handle_exception(exc)
  File "e:\Python39\venv\lib\site-packages\rest_framework\views.py", line 469, in handle_exception
    self.raise_uncaught_exception(exc)
  File "e:\Python39\venv\lib\site-packages\rest_framework\views.py", line 480, in raise_uncaught_exception
    raise exc
  File "e:\Python39\venv\lib\site-packages\rest_framework\views.py", line 506, in dispatch
    response = handler(request, *args, **kwargs)
  File "e:\Python39\venv\lib\site-packages\rest_framework\decorators.py", line 50, in handler
    return func(*args, **kwargs)
  File "E:\FessScrapper_project\FessApp\views\common.py", line 43, in Fess_split_Post
    full_path=Fess_hbr_Post(request)
  File "E:\FessScrapper_project\FessApp\views\hbr.py", line 98, in Fess_hbr_Post
    publication_date, title, text , full_path= Fetch_Content(link,collection_name)
ValueError: too many values to unpack (expected 4)
ERROR 2024-05-30 19:59:55,028 basehttp "POST /myfess/ HTTP/1.1" 500 100528
ERROR 2024-05-30 20:04:14,859 log Internal Server Error: /myfess/
Traceback (most recent call last):
  File "e:\Python39\venv\lib\site-packages\django\core\handlers\exception.py", line 55, in inner
    response = get_response(request)
  File "e:\Python39\venv\lib\site-packages\django\core\handlers\base.py", line 197, in _get_response
    response = wrapped_callback(request, *callback_args, **callback_kwargs)
  File "e:\Python39\venv\lib\site-packages\django\views\decorators\csrf.py", line 56, in wrapper_view
    return view_func(*args, **kwargs)
  File "e:\Python39\venv\lib\site-packages\django\views\generic\base.py", line 104, in view
    return self.dispatch(request, *args, **kwargs)
  File "e:\Python39\venv\lib\site-packages\rest_framework\views.py", line 509, in dispatch
    response = self.handle_exception(exc)
  File "e:\Python39\venv\lib\site-packages\rest_framework\views.py", line 469, in handle_exception
    self.raise_uncaught_exception(exc)
  File "e:\Python39\venv\lib\site-packages\rest_framework\views.py", line 480, in raise_uncaught_exception
    raise exc
  File "e:\Python39\venv\lib\site-packages\rest_framework\views.py", line 506, in dispatch
    response = handler(request, *args, **kwargs)
  File "e:\Python39\venv\lib\site-packages\rest_framework\decorators.py", line 50, in handler
    return func(*args, **kwargs)
  File "E:\FessScrapper_project\FessApp\views\common.py", line 43, in Fess_split_Post
    full_path=Fess_hbr_Post(request)
  File "E:\FessScrapper_project\FessApp\views\hbr.py", line 98, in Fess_hbr_Post
    publication_date, title, text , full_path= Fetch_Content(link,collection_name)
ValueError: too many values to unpack (expected 4)
ERROR 2024-05-30 20:04:14,872 basehttp "POST /myfess/ HTTP/1.1" 500 100748
ERROR 2024-05-30 21:25:53,714 log Internal Server Error: /myfess/
Traceback (most recent call last):
  File "e:\Python39\venv\lib\site-packages\django\core\handlers\exception.py", line 55, in inner
    response = get_response(request)
  File "e:\Python39\venv\lib\site-packages\django\core\handlers\base.py", line 197, in _get_response
    response = wrapped_callback(request, *callback_args, **callback_kwargs)
  File "e:\Python39\venv\lib\site-packages\django\views\decorators\csrf.py", line 56, in wrapper_view
    return view_func(*args, **kwargs)
  File "e:\Python39\venv\lib\site-packages\django\views\generic\base.py", line 104, in view
    return self.dispatch(request, *args, **kwargs)
  File "e:\Python39\venv\lib\site-packages\rest_framework\views.py", line 509, in dispatch
    response = self.handle_exception(exc)
  File "e:\Python39\venv\lib\site-packages\rest_framework\views.py", line 469, in handle_exception
    self.raise_uncaught_exception(exc)
  File "e:\Python39\venv\lib\site-packages\rest_framework\views.py", line 480, in raise_uncaught_exception
    raise exc
  File "e:\Python39\venv\lib\site-packages\rest_framework\views.py", line 506, in dispatch
    response = handler(request, *args, **kwargs)
  File "e:\Python39\venv\lib\site-packages\rest_framework\decorators.py", line 50, in handler
    return func(*args, **kwargs)
  File "E:\FessScrapper_project\FessApp\views\common.py", line 43, in Fess_split_Post
    full_path=Fess_hbr_Post(request)
  File "E:\FessScrapper_project\FessApp\views\hbr.py", line 99, in Fess_hbr_Post
    publication_date, title, text , full_path= Fetch_Content(link,collection_name)
ValueError: too many values to unpack (expected 4)
ERROR 2024-05-30 21:25:53,731 basehttp "POST /myfess/ HTTP/1.1" 500 100749
ERROR 2024-05-30 21:33:42,230 log Internal Server Error: /myfess/
Traceback (most recent call last):
  File "e:\Python39\venv\lib\site-packages\django\core\handlers\exception.py", line 55, in inner
    response = get_response(request)
  File "e:\Python39\venv\lib\site-packages\django\core\handlers\base.py", line 197, in _get_response
    response = wrapped_callback(request, *callback_args, **callback_kwargs)
  File "e:\Python39\venv\lib\site-packages\django\views\decorators\csrf.py", line 56, in wrapper_view
    return view_func(*args, **kwargs)
  File "e:\Python39\venv\lib\site-packages\django\views\generic\base.py", line 104, in view
    return self.dispatch(request, *args, **kwargs)
  File "e:\Python39\venv\lib\site-packages\rest_framework\views.py", line 509, in dispatch
    response = self.handle_exception(exc)
  File "e:\Python39\venv\lib\site-packages\rest_framework\views.py", line 469, in handle_exception
    self.raise_uncaught_exception(exc)
  File "e:\Python39\venv\lib\site-packages\rest_framework\views.py", line 480, in raise_uncaught_exception
    raise exc
  File "e:\Python39\venv\lib\site-packages\rest_framework\views.py", line 506, in dispatch
    response = handler(request, *args, **kwargs)
  File "e:\Python39\venv\lib\site-packages\rest_framework\decorators.py", line 50, in handler
    return func(*args, **kwargs)
  File "E:\FessScrapper_project\FessApp\views\common.py", line 43, in Fess_split_Post
    full_path=Fess_hbr_Post(request)
  File "E:\FessScrapper_project\FessApp\views\hbr.py", line 117, in Fess_hbr_Post
    hbr_rec = mycollection.insert_one(hrb_rec)
  File "e:\Python39\venv\lib\site-packages\pymongo\collection.py", line 658, in insert_one
    self._insert_one(
  File "e:\Python39\venv\lib\site-packages\pymongo\collection.py", line 598, in _insert_one
    self.__database.client._retryable_write(
  File "e:\Python39\venv\lib\site-packages\pymongo\mongo_client.py", line 1569, in _retryable_write
    return self._retry_with_session(retryable, func, s, bulk, operation, operation_id)
  File "e:\Python39\venv\lib\site-packages\pymongo\mongo_client.py", line 1455, in _retry_with_session
    return self._retry_internal(
  File "e:\Python39\venv\lib\site-packages\pymongo\_csot.py", line 108, in csot_wrapper
    return func(self, *args, **kwargs)
  File "e:\Python39\venv\lib\site-packages\pymongo\mongo_client.py", line 1490, in _retry_internal
    return _ClientConnectionRetryable(
  File "e:\Python39\venv\lib\site-packages\pymongo\mongo_client.py", line 2347, in run
    return self._read() if self._is_read else self._write()
  File "e:\Python39\venv\lib\site-packages\pymongo\mongo_client.py", line 2450, in _write
    self._server = self._get_server()
  File "e:\Python39\venv\lib\site-packages\pymongo\mongo_client.py", line 2433, in _get_server
    return self._client._select_server(
  File "e:\Python39\venv\lib\site-packages\pymongo\mongo_client.py", line 1316, in _select_server
    server = topology.select_server(
  File "e:\Python39\venv\lib\site-packages\pymongo\topology.py", line 369, in select_server
    server = self._select_server(
  File "e:\Python39\venv\lib\site-packages\pymongo\topology.py", line 347, in _select_server
    servers = self.select_servers(
  File "e:\Python39\venv\lib\site-packages\pymongo\topology.py", line 254, in select_servers
    server_descriptions = self._select_servers_loop(
  File "e:\Python39\venv\lib\site-packages\pymongo\topology.py", line 304, in _select_servers_loop
    raise ServerSelectionTimeoutError(
pymongo.errors.ServerSelectionTimeoutError: localhost:27017: [WinError 10061] No connection could be made because the target machine actively refused it (configured timeouts: socketTimeoutMS: 20000.0ms, connectTimeoutMS: 20000.0ms), Timeout: 30s, Topology Description: <TopologyDescription id: 6658a2478cab3322ffc38823, topology_type: Unknown, servers: [<ServerDescription ('localhost', 27017) server_type: Unknown, rtt: None, error=AutoReconnect('localhost:27017: [WinError 10061] No connection could be made because the target machine actively refused it (configured timeouts: socketTimeoutMS: 20000.0ms, connectTimeoutMS: 20000.0ms)')>]>
ERROR 2024-05-30 21:33:42,247 basehttp "POST /myfess/ HTTP/1.1" 500 176942
ERROR 2024-05-30 21:34:53,275 log Internal Server Error: /myfess/
Traceback (most recent call last):
  File "e:\Python39\venv\lib\site-packages\django\core\handlers\exception.py", line 55, in inner
    response = get_response(request)
  File "e:\Python39\venv\lib\site-packages\django\core\handlers\base.py", line 220, in _get_response
    response = response.render()
  File "e:\Python39\venv\lib\site-packages\django\template\response.py", line 114, in render
    self.content = self.rendered_content
  File "e:\Python39\venv\lib\site-packages\rest_framework\response.py", line 74, in rendered_content
    ret = renderer.render(self.data, accepted_media_type, context)
  File "e:\Python39\venv\lib\site-packages\rest_framework\renderers.py", line 99, in render
    ret = json.dumps(
  File "e:\Python39\venv\lib\site-packages\rest_framework\utils\json.py", line 25, in dumps
    return json.dumps(*args, **kwargs)
  File "E:\Python39\lib\json\__init__.py", line 234, in dumps
    return cls(
  File "E:\Python39\lib\json\encoder.py", line 199, in encode
    chunks = self.iterencode(o, _one_shot=True)
  File "E:\Python39\lib\json\encoder.py", line 257, in iterencode
    return _iterencode(o, 0)
  File "e:\Python39\venv\lib\site-packages\rest_framework\utils\encoders.py", line 67, in default
    return super().default(obj)
  File "E:\Python39\lib\json\encoder.py", line 179, in default
    raise TypeError(f'Object of type {o.__class__.__name__} '
TypeError: Object of type Response is not JSON serializable
ERROR 2024-05-30 21:34:53,290 basehttp "POST /myfess/ HTTP/1.1" 500 101677
ERROR 2024-05-30 21:42:27,683 log Internal Server Error: /myfess/
Traceback (most recent call last):
  File "e:\Python39\venv\lib\site-packages\django\core\handlers\exception.py", line 55, in inner
    response = get_response(request)
  File "e:\Python39\venv\lib\site-packages\django\core\handlers\base.py", line 197, in _get_response
    response = wrapped_callback(request, *callback_args, **callback_kwargs)
  File "e:\Python39\venv\lib\site-packages\django\views\decorators\csrf.py", line 56, in wrapper_view
    return view_func(*args, **kwargs)
  File "e:\Python39\venv\lib\site-packages\django\views\generic\base.py", line 104, in view
    return self.dispatch(request, *args, **kwargs)
  File "e:\Python39\venv\lib\site-packages\rest_framework\views.py", line 509, in dispatch
    response = self.handle_exception(exc)
  File "e:\Python39\venv\lib\site-packages\rest_framework\views.py", line 469, in handle_exception
    self.raise_uncaught_exception(exc)
  File "e:\Python39\venv\lib\site-packages\rest_framework\views.py", line 480, in raise_uncaught_exception
    raise exc
  File "e:\Python39\venv\lib\site-packages\rest_framework\views.py", line 506, in dispatch
    response = handler(request, *args, **kwargs)
  File "e:\Python39\venv\lib\site-packages\rest_framework\decorators.py", line 50, in handler
    return func(*args, **kwargs)
  File "E:\FessScrapper_project\FessApp\views\common.py", line 43, in Fess_split_Post
    full_path=Fess_hbr_Post(request)
  File "E:\FessScrapper_project\FessApp\views\hbr.py", line 98, in Fess_hbr_Post
    publication_date, title, text , full_path= Fetch_Content(link,collection_name)
  File "E:\FessScrapper_project\FessApp\views\hbr.py", line 23, in Fetch_Content
    file_name,file_path=generate_filname(link,collection_name)
  File "E:\FessScrapper_project\FessApp\views\Filename_generator.py", line 16, in generate_filname
    file_name = f"{collection_name}_{path_parts[2]}_{timestamp_str}"
IndexError: list index out of range
ERROR 2024-05-30 21:42:27,691 basehttp "POST /myfess/ HTTP/1.1" 500 108702
ERROR 2024-05-30 21:42:32,734 log Internal Server Error: /myfess/
Traceback (most recent call last):
  File "e:\Python39\venv\lib\site-packages\django\core\handlers\exception.py", line 55, in inner
    response = get_response(request)
  File "e:\Python39\venv\lib\site-packages\django\core\handlers\base.py", line 197, in _get_response
    response = wrapped_callback(request, *callback_args, **callback_kwargs)
  File "e:\Python39\venv\lib\site-packages\django\views\decorators\csrf.py", line 56, in wrapper_view
    return view_func(*args, **kwargs)
  File "e:\Python39\venv\lib\site-packages\django\views\generic\base.py", line 104, in view
    return self.dispatch(request, *args, **kwargs)
  File "e:\Python39\venv\lib\site-packages\rest_framework\views.py", line 509, in dispatch
    response = self.handle_exception(exc)
  File "e:\Python39\venv\lib\site-packages\rest_framework\views.py", line 469, in handle_exception
    self.raise_uncaught_exception(exc)
  File "e:\Python39\venv\lib\site-packages\rest_framework\views.py", line 480, in raise_uncaught_exception
    raise exc
  File "e:\Python39\venv\lib\site-packages\rest_framework\views.py", line 506, in dispatch
    response = handler(request, *args, **kwargs)
  File "e:\Python39\venv\lib\site-packages\rest_framework\decorators.py", line 50, in handler
    return func(*args, **kwargs)
  File "E:\FessScrapper_project\FessApp\views\common.py", line 43, in Fess_split_Post
    full_path=Fess_hbr_Post(request)
  File "E:\FessScrapper_project\FessApp\views\hbr.py", line 98, in Fess_hbr_Post
    publication_date, title, text , full_path= Fetch_Content(link,collection_name)
  File "E:\FessScrapper_project\FessApp\views\hbr.py", line 23, in Fetch_Content
    file_name,file_path=generate_filname(link,collection_name)
  File "E:\FessScrapper_project\FessApp\views\Filename_generator.py", line 16, in generate_filname
    file_name = f"{collection_name}_{path_parts[2]}_{timestamp_str}"
IndexError: list index out of range
ERROR 2024-05-30 21:42:32,734 basehttp "POST /myfess/ HTTP/1.1" 500 108702
ERROR 2024-05-30 21:54:11,164 log Internal Server Error: /myfess/
Traceback (most recent call last):
  File "e:\Python39\venv\lib\site-packages\django\core\handlers\exception.py", line 55, in inner
    response = get_response(request)
  File "e:\Python39\venv\lib\site-packages\django\core\handlers\base.py", line 197, in _get_response
    response = wrapped_callback(request, *callback_args, **callback_kwargs)
  File "e:\Python39\venv\lib\site-packages\django\views\decorators\csrf.py", line 56, in wrapper_view
    return view_func(*args, **kwargs)
  File "e:\Python39\venv\lib\site-packages\django\views\generic\base.py", line 104, in view
    return self.dispatch(request, *args, **kwargs)
  File "e:\Python39\venv\lib\site-packages\rest_framework\views.py", line 509, in dispatch
    response = self.handle_exception(exc)
  File "e:\Python39\venv\lib\site-packages\rest_framework\views.py", line 469, in handle_exception
    self.raise_uncaught_exception(exc)
  File "e:\Python39\venv\lib\site-packages\rest_framework\views.py", line 480, in raise_uncaught_exception
    raise exc
  File "e:\Python39\venv\lib\site-packages\rest_framework\views.py", line 506, in dispatch
    response = handler(request, *args, **kwargs)
  File "e:\Python39\venv\lib\site-packages\rest_framework\decorators.py", line 50, in handler
    return func(*args, **kwargs)
  File "E:\FessScrapper_project\FessApp\views\common.py", line 41, in Fess_split_Post
    full_path=Fess_Sodalitas_Post(request)
  File "E:\FessScrapper_project\FessApp\views\sodalitas.py", line 124, in Fess_Sodalitas_Post
    publication_date, title, text , full_path= Fetch_Content(link,collection_name)
  File "E:\FessScrapper_project\FessApp\views\sodalitas.py", line 45, in Fetch_Content
    file_name,file_path=generate_filname(link,collection_name)
  File "E:\FessScrapper_project\FessApp\views\sodalitas.py", line 35, in generate_filname
    file_name = f"{collection_name}_{path_parts[2]}_{timestamp_str}"
IndexError: list index out of range
ERROR 2024-05-30 21:54:11,168 basehttp "POST /myfess/ HTTP/1.1" 500 109434
